<?xml version="1.0" ?>
<!-- =================================================================================== -->
<!-- |    This document was autogenerated by xacro from urdf/irb4600_60_205.xacro      | -->
<!-- |    EDITING THIS FILE BY HAND IS NOT RECOMMENDED                                 | -->
<!-- =================================================================================== -->
<robot xmlns:xacro="http://ros.org/wiki/xacro" name="abb_irb4600_60_205">
  <link name="base_link">
    <collision name="collision">
      <geometry>
        <mesh filename="package://abb_irb4600_support/meshes/base/collision/base.stl"/>
      </geometry>
    </collision>
    <visual name="visual">
      <geometry>
        <mesh filename="package://abb_irb4600_support/meshes/base/visual/base.stl"/>
      </geometry>
      <material name="red">
        <color rgba="1 0 0 1"/>
      </material>
    </visual>
  </link>
  <link name="wheel_l1">
    <collision name="collision">
      <geometry>
        <mesh filename="package://abb_irb4600_support/meshes/base/collision/wheel_l1.stl"/>
      </geometry>
    </collision>
    <visual name="visual">
      <geometry>
        <mesh filename="package://abb_irb4600_support/meshes/base/visual/wheel_l1.stl"/>
      </geometry>
      <!-- <material name="yellow"/> -->
    </visual>
  </link>
  <link name="wheel_l2">
    <collision name="collision">
      <geometry>
        <mesh filename="package://abb_irb4600_support/meshes/base/collision/wheel_l2.stl"/>
      </geometry>
    </collision>
    <visual name="visual">
      <geometry>
        <mesh filename="package://abb_irb4600_support/meshes/base/visual/wheel_l2.stl"/>
      </geometry>
      <!-- <material name="yellow"/> -->
    </visual>
  </link>
  <link name="wheel_r1">
    <collision name="collision">
      <geometry>
        <mesh filename="package://abb_irb4600_support/meshes/base/collision/wheel_r1.stl"/>
      </geometry>
    </collision>
    <visual name="visual">
      <geometry>
        <mesh filename="package://abb_irb4600_support/meshes/base/visual/wheel_r1.stl"/>
      </geometry>
      <!-- <material name="yellow"/> -->
    </visual>
  </link>
  <link name="wheel_r2">
    <collision name="collision">
      <geometry>
        <mesh filename="package://abb_irb4600_support/meshes/base/collision/wheel_r2.stl"/>
      </geometry>
    </collision>
    <visual name="visual">
      <geometry>
        <mesh filename="package://abb_irb4600_support/meshes/base/visual/wheel_r2.stl"/>
      </geometry>
      <!-- <material name="yellow"/> -->
    </visual>
  </link>
  <!-- <link name="link_5">
    <collision name="collision">
      <geometry>
        <mesh filename="package://abb_irb4600_support/meshes/irb4600_60_205/collision/link_5.stl"/>
      </geometry>
    </collision>
    <visual name="visual">
      <geometry>
        <mesh filename="package://abb_irb4600_support/meshes/irb4600_60_205/visual/link_5.stl"/>
      </geometry>
      <material name="yellow"/>
    </visual>
  </link> -->
  <!-- <link name="link_6">
    <collision name="collision">
      <geometry>
        <mesh filename="package://abb_irb4600_support/meshes/irb4600_60_205/collision/link_6.stl"/>
      </geometry>
    </collision>
    <visual name="visual">
      <geometry>
        <mesh filename="package://abb_irb4600_support/meshes/irb4600_60_205/visual/link_6.stl"/>
      </geometry>
      <material name="yellow"/>
    </visual>
  </link>
  <link name="tool0"/> -->
  <joint type="revolute" name="joint_1">
    <!-- <origin xyz="0.8 0.65 0" rpy="0 0 0"/> -->
    <axis xyz="0 1 0"/>
    <parent link="base_link"/>
    <child link="wheel_l1"/>
    <!-- <limit effort="0" lower="-3.141" upper="3.141" velocity="3.054"/> -->
  </joint>
  <joint type="revolute" name="joint_2">
    <!-- <origin xyz="-0.8 0.65 0" rpy="0 0 0"/> -->
    <axis xyz="0 1 0"/>
    <parent link="base_link"/>
    <child link="wheel_r1"/>
    <!-- <limit effort="0" lower="-1.570" upper="2.617" velocity="3.054"/> -->
  </joint>
  <joint type="revolute" name="joint_3">
    <!-- <origin xyz="0.8 -0.65 0" rpy="0 0 0"/> -->
    <axis xyz="0 1 0"/>
    <parent link="base_link"/>
    <child link="wheel_l2"/>
    <!-- <limit effort="0" lower="-3.141" upper="1.308" velocity="3.054"/> -->
  </joint>
  <joint type="revolute" name="joint_4">
    <!-- <origin xyz="-0.8 -0.65 0" rpy="0 0 0"/> -->
    <axis xyz="0 1 0"/>
    <parent link="base_link"/>
    <child link="wheel_r2"/>
    <!-- <limit effort="0" lower="-6.981" upper="6.981" velocity="4.363"/> -->
  </joint>
  <!-- <joint type="revolute" name="joint_5">
    <origin xyz="0.960 0 0 " rpy="0 0 0"/>
    <axis xyz="0 1 0"/>
    <parent link="link_4"/>
    <child link="link_5"/>
    <limit effort="0" lower="-2.181" upper="2.094" velocity="4.363"/>
  </joint>
  <joint type="revolute" name="joint_6">
    <origin xyz="0.135 0 0 " rpy="0 0 0"/>
    <axis xyz="1 0 0"/>
    <parent link="link_5"/>
    <child link="link_6"/>
    <limit effort="0" lower="-6.981" upper="6.981" velocity="6.283"/>
  </joint>
  <joint type="fixed" name="joint_6-tool0">
    <parent link="link_6"/>
    <child link="tool0"/>
    <origin xyz="0 0 0" rpy="0 1.57079632679 0"/>
  </joint>
  <link name="base"/>
  <joint name="base_link-base" type="fixed">
    <origin xyz="0 0 0" rpy="0 0 0"/>
    <parent link="base_link"/>
    <child link="base"/>
  </joint> -->
</robot>
